2023-05-27 02:53:39,282 DEBUG  /usr/local/Cellar/python@3.11/3.11.3/Frameworks/Python.framework/Versions/3.11/lib/python3.11/asyncio/selector_events.py:54:__init__: Using selector: KqueueSelector
2023-05-27 02:53:39,283 INFO  /Users/ljh/Documents/asyncio/src/client/client.py:37:main: connecting to 192.168.1.31:8888
2023-05-27 02:53:39,284 INFO  /Users/ljh/Documents/asyncio/src/server/server.py:13:handle_conn: accepting connection from ('192.168.1.31', 51326)
2023-05-27 02:53:41,575 INFO  /Users/ljh/Documents/asyncio/src/client/client.py:28:handle_conn: 
2023-05-27 02:53:41,576 INFO  /Users/ljh/Documents/asyncio/src/client/client.py:46:<module>: 
2023-05-27 02:53:41,576 INFO  /Users/ljh/Documents/asyncio/src/server/server.py:33:handle_conn: Connection lost
2023-05-27 02:53:43,246 DEBUG  /usr/local/Cellar/python@3.11/3.11.3/Frameworks/Python.framework/Versions/3.11/lib/python3.11/asyncio/selector_events.py:54:__init__: Using selector: KqueueSelector
2023-05-27 02:53:43,247 INFO  /Users/ljh/Documents/asyncio/src/client/client.py:37:main: connecting to 192.168.1.31:8888
2023-05-27 02:53:43,247 INFO  /Users/ljh/Documents/asyncio/src/server/server.py:13:handle_conn: accepting connection from ('192.168.1.31', 51327)
2023-05-27 02:53:44,223 INFO  /Users/ljh/Documents/asyncio/src/client/client.py:28:handle_conn: 
2023-05-27 02:53:44,224 INFO  /Users/ljh/Documents/asyncio/src/server/server.py:33:handle_conn: Connection lost
2023-05-27 02:53:46,175 DEBUG  /usr/local/Cellar/python@3.11/3.11.3/Frameworks/Python.framework/Versions/3.11/lib/python3.11/asyncio/selector_events.py:54:__init__: Using selector: KqueueSelector
2023-05-27 02:53:46,176 INFO  /Users/ljh/Documents/asyncio/src/client/client.py:37:main: connecting to 192.168.1.31:8888
2023-05-27 02:53:46,177 INFO  /Users/ljh/Documents/asyncio/src/server/server.py:13:handle_conn: accepting connection from ('192.168.1.31', 51328)
2023-05-27 02:53:48,253 DEBUG  /usr/local/Cellar/python@3.11/3.11.3/Frameworks/Python.framework/Versions/3.11/lib/python3.11/asyncio/selector_events.py:54:__init__: Using selector: KqueueSelector
2023-05-27 02:53:48,254 INFO  /Users/ljh/Documents/asyncio/src/client/client.py:37:main: connecting to 192.168.1.31:8888
2023-05-27 02:53:48,255 INFO  /Users/ljh/Documents/asyncio/src/server/server.py:13:handle_conn: accepting connection from ('192.168.1.31', 51329)
2023-05-27 02:53:51,025 INFO  /Users/ljh/Documents/asyncio/src/server/server.py:33:handle_conn: 
2023-05-27 02:53:51,028 INFO  /Users/ljh/Documents/asyncio/src/client/client.py:28:handle_conn: Connection lost
2023-05-27 02:53:51,439 INFO  /Users/ljh/Documents/asyncio/src/server/server.py:59:<module>: 
2023-05-27 02:53:51,448 ERROR  /usr/local/Cellar/python@3.11/3.11.3/Frameworks/Python.framework/Versions/3.11/lib/python3.11/asyncio/base_events.py:1771:default_exception_handler: Task was destroyed but it is pending!
task: <Task pending name='Task-21380' coro=<StreamReader.read() done, defined at /usr/local/Cellar/python@3.11/3.11.3/Frameworks/Python.framework/Versions/3.11/lib/python3.11/asyncio/streams.py:648> wait_for=<Future pending cb=[Task.task_wakeup()]> cb=[_release_waiter(<Future pendi...ask_wakeup()]>)() at /usr/local/Cellar/python@3.11/3.11.3/Frameworks/Python.framework/Versions/3.11/lib/python3.11/asyncio/tasks.py:421]>
2023-05-27 02:53:51,448 ERROR  /usr/local/Cellar/python@3.11/3.11.3/Frameworks/Python.framework/Versions/3.11/lib/python3.11/asyncio/base_events.py:1771:default_exception_handler: Task was destroyed but it is pending!
task: <Task cancelling name='Task-7435' coro=<handle_conn() running at /Users/ljh/Documents/asyncio/src/server/server.py:22> wait_for=<Future pending cb=[Task.task_wakeup()]> cb=[gather.<locals>._done_callback() at /usr/local/Cellar/python@3.11/3.11.3/Frameworks/Python.framework/Versions/3.11/lib/python3.11/asyncio/tasks.py:754]>
2023-05-27 02:53:51,448 INFO  /Users/ljh/Documents/asyncio/src/server/server.py:33:handle_conn: 
2023-05-27 02:53:51,455 INFO  /Users/ljh/Documents/asyncio/src/client/client.py:28:handle_conn: Connection lost
2023-05-27 02:58:07,909 DEBUG  /usr/local/Cellar/python@3.11/3.11.3/Frameworks/Python.framework/Versions/3.11/lib/python3.11/asyncio/selector_events.py:54:__init__: Using selector: KqueueSelector
2023-05-27 02:58:07,914 INFO  /Users/ljh/Documents/asyncio/src/server/server.py:44:main: serving on ('::', 8888, 0, 0), ('0.0.0.0', 8888)
2023-05-27 02:58:10,304 DEBUG  /usr/local/Cellar/python@3.11/3.11.3/Frameworks/Python.framework/Versions/3.11/lib/python3.11/asyncio/selector_events.py:54:__init__: Using selector: KqueueSelector
2023-05-27 02:58:10,305 INFO  /Users/ljh/Documents/asyncio/src/client/client.py:37:main: connecting to 192.168.1.31:8888
2023-05-27 02:58:10,306 INFO  /Users/ljh/Documents/asyncio/src/server/server.py:13:handle_conn: accepting connection from ('192.168.1.31', 51401)
2023-05-27 02:58:12,309 DEBUG  /usr/local/Cellar/python@3.11/3.11.3/Frameworks/Python.framework/Versions/3.11/lib/python3.11/asyncio/selector_events.py:54:__init__: Using selector: KqueueSelector
2023-05-27 02:58:12,310 INFO  /Users/ljh/Documents/asyncio/src/client/client.py:37:main: connecting to 192.168.1.31:8888
2023-05-27 02:58:12,311 INFO  /Users/ljh/Documents/asyncio/src/server/server.py:13:handle_conn: accepting connection from ('192.168.1.31', 51402)
2023-05-27 02:58:24,159 INFO  /Users/ljh/Documents/asyncio/src/server/server.py:33:handle_conn: 
2023-05-27 02:58:24,160 INFO  /Users/ljh/Documents/asyncio/src/client/client.py:28:handle_conn: Connection lost
2023-05-27 02:58:28,123 INFO  /Users/ljh/Documents/asyncio/src/server/server.py:30:handle_conn: 
2023-05-27 02:58:28,124 INFO  /Users/ljh/Documents/asyncio/src/client/client.py:28:handle_conn: [Errno 54] Connection reset by peer
2023-05-27 02:58:28,124 INFO  /Users/ljh/Documents/asyncio/src/server/server.py:59:<module>: 
2023-05-27 02:59:08,801 DEBUG  /usr/local/Cellar/python@3.11/3.11.3/Frameworks/Python.framework/Versions/3.11/lib/python3.11/asyncio/selector_events.py:54:__init__: Using selector: KqueueSelector
2023-05-27 02:59:08,804 INFO  /Users/ljh/Documents/asyncio/src/server/server.py:44:main: serving on ('0.0.0.0', 8888), ('::', 8888, 0, 0)
2023-05-27 02:59:11,723 DEBUG  /usr/local/Cellar/python@3.11/3.11.3/Frameworks/Python.framework/Versions/3.11/lib/python3.11/asyncio/selector_events.py:54:__init__: Using selector: KqueueSelector
2023-05-27 02:59:11,723 INFO  /Users/ljh/Documents/asyncio/src/client/client.py:37:main: connecting to 192.168.1.31:8888
2023-05-27 02:59:11,725 INFO  /Users/ljh/Documents/asyncio/src/server/server.py:13:handle_conn: accepting connection from ('192.168.1.31', 51406)
2023-05-27 02:59:13,666 DEBUG  /usr/local/Cellar/python@3.11/3.11.3/Frameworks/Python.framework/Versions/3.11/lib/python3.11/asyncio/selector_events.py:54:__init__: Using selector: KqueueSelector
2023-05-27 02:59:13,667 INFO  /Users/ljh/Documents/asyncio/src/client/client.py:37:main: connecting to 192.168.1.31:8888
2023-05-27 02:59:13,669 INFO  /Users/ljh/Documents/asyncio/src/server/server.py:13:handle_conn: accepting connection from ('192.168.1.31', 51409)
2023-05-27 02:59:15,826 INFO  /Users/ljh/Documents/asyncio/src/server/server.py:33:handle_conn: 
2023-05-27 02:59:15,826 INFO  /Users/ljh/Documents/asyncio/src/server/server.py:33:handle_conn: 
2023-05-27 02:59:15,827 INFO  /Users/ljh/Documents/asyncio/src/client/client.py:28:handle_conn: [Errno 54] Connection reset by peer
2023-05-27 02:59:15,827 INFO  /Users/ljh/Documents/asyncio/src/client/client.py:28:handle_conn: Connection lost
2023-05-27 02:59:15,828 INFO  /Users/ljh/Documents/asyncio/src/server/server.py:59:<module>: 
2023-05-27 02:59:18,620 DEBUG  /usr/local/Cellar/python@3.11/3.11.3/Frameworks/Python.framework/Versions/3.11/lib/python3.11/asyncio/selector_events.py:54:__init__: Using selector: KqueueSelector
2023-05-27 02:59:18,624 INFO  /Users/ljh/Documents/asyncio/src/server/server.py:44:main: serving on ('0.0.0.0', 8888), ('::', 8888, 0, 0)
2023-05-27 02:59:21,360 DEBUG  /usr/local/Cellar/python@3.11/3.11.3/Frameworks/Python.framework/Versions/3.11/lib/python3.11/asyncio/selector_events.py:54:__init__: Using selector: KqueueSelector
2023-05-27 02:59:21,360 INFO  /Users/ljh/Documents/asyncio/src/client/client.py:37:main: connecting to 192.168.1.31:8888
2023-05-27 02:59:21,362 INFO  /Users/ljh/Documents/asyncio/src/server/server.py:13:handle_conn: accepting connection from ('192.168.1.31', 51410)
2023-05-27 02:59:23,255 DEBUG  /usr/local/Cellar/python@3.11/3.11.3/Frameworks/Python.framework/Versions/3.11/lib/python3.11/asyncio/selector_events.py:54:__init__: Using selector: KqueueSelector
2023-05-27 02:59:23,256 INFO  /Users/ljh/Documents/asyncio/src/client/client.py:37:main: connecting to 192.168.1.31:8888
2023-05-27 02:59:23,257 INFO  /Users/ljh/Documents/asyncio/src/server/server.py:13:handle_conn: accepting connection from ('192.168.1.31', 51412)
2023-05-27 02:59:45,536 INFO  /Users/ljh/Documents/asyncio/src/server/server.py:33:handle_conn: 
2023-05-27 02:59:45,537 INFO  /Users/ljh/Documents/asyncio/src/client/client.py:28:handle_conn: Connection lost
2023-05-27 02:59:49,403 INFO  /Users/ljh/Documents/asyncio/src/server/server.py:59:<module>: 
2023-05-27 02:59:49,411 ERROR  /usr/local/Cellar/python@3.11/3.11.3/Frameworks/Python.framework/Versions/3.11/lib/python3.11/asyncio/base_events.py:1771:default_exception_handler: Task was destroyed but it is pending!
task: <Task pending name='Task-75552' coro=<StreamReader.read() running at /usr/local/Cellar/python@3.11/3.11.3/Frameworks/Python.framework/Versions/3.11/lib/python3.11/asyncio/streams.py:648> cb=[_release_waiter(<Future pendi...ask_wakeup()]>)() at /usr/local/Cellar/python@3.11/3.11.3/Frameworks/Python.framework/Versions/3.11/lib/python3.11/asyncio/tasks.py:421]>
2023-05-27 02:59:49,412 INFO  /Users/ljh/Documents/asyncio/src/client/client.py:28:handle_conn: [Errno 54] Connection reset by peer
2023-05-27 02:59:49,414 INFO  /Users/ljh/Documents/asyncio/src/server/server.py:33:handle_conn: 
2023-05-27 02:59:49,419 ERROR  /usr/local/Cellar/python@3.11/3.11.3/Frameworks/Python.framework/Versions/3.11/lib/python3.11/asyncio/base_events.py:1771:default_exception_handler: Task was destroyed but it is pending!
task: <Task cancelling name='Task-4' coro=<handle_conn() done, defined at /Users/ljh/Documents/asyncio/src/server/server.py:10> wait_for=<Future pending cb=[Task.task_wakeup()]> cb=[gather.<locals>._done_callback() at /usr/local/Cellar/python@3.11/3.11.3/Frameworks/Python.framework/Versions/3.11/lib/python3.11/asyncio/tasks.py:754]>
2023-05-27 03:00:55,294 DEBUG  /usr/local/Cellar/python@3.11/3.11.3/Frameworks/Python.framework/Versions/3.11/lib/python3.11/asyncio/selector_events.py:54:__init__: Using selector: KqueueSelector
2023-05-27 03:00:55,296 INFO  /Users/ljh/Documents/asyncio/src/client/client.py:37:main: connecting to 192.168.1.4:8888
2023-05-27 03:00:58,908 INFO  /Users/ljh/Documents/asyncio/src/client/client.py:46:<module>: 
2023-05-27 03:01:02,177 DEBUG  /usr/local/Cellar/python@3.11/3.11.3/Frameworks/Python.framework/Versions/3.11/lib/python3.11/asyncio/selector_events.py:54:__init__: Using selector: KqueueSelector
2023-05-27 03:01:02,178 INFO  /Users/ljh/Documents/asyncio/src/client/client.py:37:main: connecting to 192.168.1.31:8888
2023-05-27 03:01:02,179 INFO  /Users/ljh/Documents/asyncio/src/client/client.py:46:<module>: [Errno 61] Connect call failed ('192.168.1.31', 8888)
2023-05-27 03:01:49,662 DEBUG  /usr/local/Cellar/python@3.11/3.11.3/Frameworks/Python.framework/Versions/3.11/lib/python3.11/asyncio/selector_events.py:54:__init__: Using selector: KqueueSelector
2023-05-27 03:01:49,665 INFO  /Users/ljh/Documents/asyncio/src/server/server.py:44:main: serving on ('0.0.0.0', 8888), ('::', 8888, 0, 0)
2023-05-27 03:01:52,180 DEBUG  /usr/local/Cellar/python@3.11/3.11.3/Frameworks/Python.framework/Versions/3.11/lib/python3.11/asyncio/selector_events.py:54:__init__: Using selector: KqueueSelector
2023-05-27 03:01:52,180 INFO  /Users/ljh/Documents/asyncio/src/client/client.py:37:main: connecting to 192.168.1.31:8888
2023-05-27 03:01:52,181 INFO  /Users/ljh/Documents/asyncio/src/server/server.py:13:handle_conn: accepting connection from ('192.168.1.31', 51432)
2023-05-27 03:01:54,094 DEBUG  /usr/local/Cellar/python@3.11/3.11.3/Frameworks/Python.framework/Versions/3.11/lib/python3.11/asyncio/selector_events.py:54:__init__: Using selector: KqueueSelector
2023-05-27 03:01:54,095 INFO  /Users/ljh/Documents/asyncio/src/client/client.py:37:main: connecting to 192.168.1.31:8888
2023-05-27 03:01:54,096 INFO  /Users/ljh/Documents/asyncio/src/server/server.py:13:handle_conn: accepting connection from ('192.168.1.31', 51433)
2023-05-27 03:01:57,499 DEBUG  /usr/local/Cellar/python@3.11/3.11.3/Frameworks/Python.framework/Versions/3.11/lib/python3.11/asyncio/selector_events.py:54:__init__: Using selector: KqueueSelector
2023-05-27 03:01:57,502 INFO  /Users/ljh/Documents/asyncio/src/client/client.py:37:main: connecting to 192.168.1.31:8888
2023-05-27 03:01:57,504 INFO  /Users/ljh/Documents/asyncio/src/server/server.py:13:handle_conn: accepting connection from ('192.168.1.31', 51434)
2023-05-27 03:02:03,231 INFO  /Users/ljh/Documents/asyncio/src/client/client.py:25:handle_conn: 
2023-05-27 03:02:03,235 INFO  /Users/ljh/Documents/asyncio/src/client/client.py:25:handle_conn: 
2023-05-27 03:02:08,610 INFO  /Users/ljh/Documents/asyncio/src/client/client.py:25:handle_conn: 
2023-05-27 03:02:08,610 INFO  /Users/ljh/Documents/asyncio/src/client/client.py:25:handle_conn: 
2023-05-27 03:02:08,610 INFO  /Users/ljh/Documents/asyncio/src/client/client.py:25:handle_conn: 
2023-05-27 03:02:19,132 INFO  /Users/ljh/Documents/asyncio/src/server/server.py:33:handle_conn: 
2023-05-27 03:02:19,135 INFO  /Users/ljh/Documents/asyncio/src/client/client.py:28:handle_conn: Connection lost
2023-05-27 03:02:19,519 INFO  /Users/ljh/Documents/asyncio/src/client/client.py:25:handle_conn: 
2023-05-27 03:02:19,519 INFO  /Users/ljh/Documents/asyncio/src/client/client.py:25:handle_conn: 
2023-05-27 03:02:19,525 INFO  /Users/ljh/Documents/asyncio/src/server/server.py:27:handle_conn: 
2023-05-27 03:02:23,504 INFO  /Users/ljh/Documents/asyncio/src/server/server.py:30:handle_conn: 
2023-05-27 03:02:23,508 INFO  /Users/ljh/Documents/asyncio/src/client/client.py:28:handle_conn: [Errno 54] Connection reset by peer
2023-05-27 03:02:27,687 INFO  /Users/ljh/Documents/asyncio/src/server/server.py:59:<module>: 
2023-05-27 03:02:27,695 ERROR  /usr/local/Cellar/python@3.11/3.11.3/Frameworks/Python.framework/Versions/3.11/lib/python3.11/asyncio/base_events.py:1771:default_exception_handler: Task was destroyed but it is pending!
task: <Task pending name='Task-55450' coro=<StreamReader.read() running at /usr/local/Cellar/python@3.11/3.11.3/Frameworks/Python.framework/Versions/3.11/lib/python3.11/asyncio/streams.py:648> cb=[_release_waiter(<Future pendi...ask_wakeup()]>)() at /usr/local/Cellar/python@3.11/3.11.3/Frameworks/Python.framework/Versions/3.11/lib/python3.11/asyncio/tasks.py:421]>
2023-05-27 03:02:27,696 ERROR  /usr/local/Cellar/python@3.11/3.11.3/Frameworks/Python.framework/Versions/3.11/lib/python3.11/asyncio/base_events.py:1771:default_exception_handler: Task was destroyed but it is pending!
task: <Task cancelling name='Task-13656' coro=<handle_conn() running at /Users/ljh/Documents/asyncio/src/server/server.py:22> wait_for=<Future pending cb=[Task.task_wakeup()]> cb=[gather.<locals>._done_callback() at /usr/local/Cellar/python@3.11/3.11.3/Frameworks/Python.framework/Versions/3.11/lib/python3.11/asyncio/tasks.py:754]>
2023-05-27 03:02:27,696 INFO  /Users/ljh/Documents/asyncio/src/server/server.py:33:handle_conn: 
2023-05-27 03:02:27,698 INFO  /Users/ljh/Documents/asyncio/src/client/client.py:28:handle_conn: [Errno 54] Connection reset by peer
2023-05-27 03:02:46,413 DEBUG  /usr/local/Cellar/python@3.11/3.11.3/Frameworks/Python.framework/Versions/3.11/lib/python3.11/asyncio/selector_events.py:54:__init__: Using selector: KqueueSelector
2023-05-27 03:02:46,419 INFO  /Users/ljh/Documents/asyncio/src/server/server.py:44:main: serving on ('0.0.0.0', 8888), ('::', 8888, 0, 0)
2023-05-27 03:02:49,351 INFO  /Users/ljh/Documents/asyncio/src/server/server.py:59:<module>: 
2023-05-27 03:02:50,334 DEBUG  /usr/local/Cellar/python@3.11/3.11.3/Frameworks/Python.framework/Versions/3.11/lib/python3.11/asyncio/selector_events.py:54:__init__: Using selector: KqueueSelector
2023-05-27 03:02:50,337 INFO  /Users/ljh/Documents/asyncio/src/server/server.py:44:main: serving on ('0.0.0.0', 8888), ('::', 8888, 0, 0)
2023-05-27 03:02:51,735 INFO  /Users/ljh/Documents/asyncio/src/server/server.py:59:<module>: 
2023-05-27 03:02:52,896 DEBUG  /usr/local/Cellar/python@3.11/3.11.3/Frameworks/Python.framework/Versions/3.11/lib/python3.11/asyncio/selector_events.py:54:__init__: Using selector: KqueueSelector
2023-05-27 03:02:52,899 INFO  /Users/ljh/Documents/asyncio/src/server/server.py:44:main: serving on ('::', 8888, 0, 0), ('0.0.0.0', 8888)
2023-05-27 03:02:54,974 DEBUG  /usr/local/Cellar/python@3.11/3.11.3/Frameworks/Python.framework/Versions/3.11/lib/python3.11/asyncio/selector_events.py:54:__init__: Using selector: KqueueSelector
2023-05-27 03:02:54,975 INFO  /Users/ljh/Documents/asyncio/src/client/client.py:37:main: connecting to 192.168.1.31:8888
2023-05-27 03:02:54,976 INFO  /Users/ljh/Documents/asyncio/src/server/server.py:13:handle_conn: accepting connection from ('192.168.1.31', 51474)
2023-05-27 03:02:56,707 DEBUG  /usr/local/Cellar/python@3.11/3.11.3/Frameworks/Python.framework/Versions/3.11/lib/python3.11/asyncio/selector_events.py:54:__init__: Using selector: KqueueSelector
2023-05-27 03:02:56,708 INFO  /Users/ljh/Documents/asyncio/src/client/client.py:37:main: connecting to 192.168.1.31:8888
2023-05-27 03:02:56,709 INFO  /Users/ljh/Documents/asyncio/src/server/server.py:13:handle_conn: accepting connection from ('192.168.1.31', 51475)
2023-05-27 03:02:58,352 DEBUG  /usr/local/Cellar/python@3.11/3.11.3/Frameworks/Python.framework/Versions/3.11/lib/python3.11/asyncio/selector_events.py:54:__init__: Using selector: KqueueSelector
2023-05-27 03:02:58,353 INFO  /Users/ljh/Documents/asyncio/src/client/client.py:37:main: connecting to 192.168.1.31:8888
2023-05-27 03:02:58,354 INFO  /Users/ljh/Documents/asyncio/src/server/server.py:13:handle_conn: accepting connection from ('192.168.1.31', 51476)
2023-05-27 03:03:32,573 INFO  /Users/ljh/Documents/asyncio/src/server/server.py:59:<module>: 
2023-05-27 03:03:32,598 INFO  /Users/ljh/Documents/asyncio/src/client/client.py:28:handle_conn: Connection lost
2023-05-27 03:03:32,598 INFO  /Users/ljh/Documents/asyncio/src/client/client.py:28:handle_conn: Connection lost
2023-05-27 03:03:32,597 INFO  /Users/ljh/Documents/asyncio/src/client/client.py:28:handle_conn: [Errno 54] Connection reset by peer
2023-05-27 03:03:38,051 DEBUG  /usr/local/Cellar/python@3.11/3.11.3/Frameworks/Python.framework/Versions/3.11/lib/python3.11/asyncio/selector_events.py:54:__init__: Using selector: KqueueSelector
2023-05-27 03:03:38,054 INFO  /Users/ljh/Documents/asyncio/src/server/server.py:44:main: serving on ('0.0.0.0', 8888), ('::', 8888, 0, 0)
2023-05-27 03:03:40,113 INFO  /Users/ljh/Documents/asyncio/src/server/server.py:59:<module>: 
2023-05-27 03:03:41,073 DEBUG  /usr/local/Cellar/python@3.11/3.11.3/Frameworks/Python.framework/Versions/3.11/lib/python3.11/asyncio/selector_events.py:54:__init__: Using selector: KqueueSelector
2023-05-27 03:03:41,076 INFO  /Users/ljh/Documents/asyncio/src/server/server.py:44:main: serving on ('0.0.0.0', 8888), ('::', 8888, 0, 0)
2023-05-27 03:03:41,865 INFO  /Users/ljh/Documents/asyncio/src/server/server.py:59:<module>: 
2023-05-27 03:03:42,866 DEBUG  /usr/local/Cellar/python@3.11/3.11.3/Frameworks/Python.framework/Versions/3.11/lib/python3.11/asyncio/selector_events.py:54:__init__: Using selector: KqueueSelector
2023-05-27 03:03:42,870 INFO  /Users/ljh/Documents/asyncio/src/server/server.py:44:main: serving on ('::', 8888, 0, 0), ('0.0.0.0', 8888)
2023-05-27 03:03:45,878 DEBUG  /usr/local/Cellar/python@3.11/3.11.3/Frameworks/Python.framework/Versions/3.11/lib/python3.11/asyncio/selector_events.py:54:__init__: Using selector: KqueueSelector
2023-05-27 03:03:45,879 INFO  /Users/ljh/Documents/asyncio/src/client/client.py:37:main: connecting to 192.168.1.31:8888
2023-05-27 03:03:45,880 INFO  /Users/ljh/Documents/asyncio/src/server/server.py:13:handle_conn: accepting connection from ('192.168.1.31', 51479)
2023-05-27 03:03:47,529 DEBUG  /usr/local/Cellar/python@3.11/3.11.3/Frameworks/Python.framework/Versions/3.11/lib/python3.11/asyncio/selector_events.py:54:__init__: Using selector: KqueueSelector
2023-05-27 03:03:47,530 INFO  /Users/ljh/Documents/asyncio/src/client/client.py:37:main: connecting to 192.168.1.31:8888
2023-05-27 03:03:47,531 INFO  /Users/ljh/Documents/asyncio/src/server/server.py:13:handle_conn: accepting connection from ('192.168.1.31', 51480)
2023-05-27 03:03:49,701 DEBUG  /usr/local/Cellar/python@3.11/3.11.3/Frameworks/Python.framework/Versions/3.11/lib/python3.11/asyncio/selector_events.py:54:__init__: Using selector: KqueueSelector
2023-05-27 03:03:49,702 INFO  /Users/ljh/Documents/asyncio/src/client/client.py:37:main: connecting to 192.168.1.31:8888
2023-05-27 03:03:49,703 INFO  /Users/ljh/Documents/asyncio/src/server/server.py:13:handle_conn: accepting connection from ('192.168.1.31', 51483)
2023-05-27 03:04:26,411 INFO  /Users/ljh/Documents/asyncio/src/server/server.py:59:<module>: 
2023-05-27 03:04:26,427 INFO  /Users/ljh/Documents/asyncio/src/client/client.py:28:handle_conn: [Errno 54] Connection reset by peer
2023-05-27 03:04:26,427 INFO  /Users/ljh/Documents/asyncio/src/client/client.py:28:handle_conn: Connection lost
2023-05-27 03:04:26,428 INFO  /Users/ljh/Documents/asyncio/src/client/client.py:28:handle_conn: Connection lost
Using selector: KqueueSelector
serving on ('0.0.0.0', 8888), ('::', 8888, 0, 0)

Using selector: KqueueSelector
serving on ('::', 8888, 0, 0), ('0.0.0.0', 8888)

Using selector: KqueueSelector
connecting to 192.168.1.31:8888
[Errno 61] Connect call failed ('192.168.1.31', 8888)
Using selector: KqueueSelector
connecting to 192.168.1.31:8888
[Errno 61] Connect call failed ('192.168.1.31', 8888)
Using selector: KqueueSelector
serving on ('::', 8888, 0, 0), ('0.0.0.0', 8888)
Using selector: KqueueSelector
connecting to 192.168.1.31:8888
accepting connection from ('192.168.1.31', 51939)
Using selector: KqueueSelector
connecting to 192.168.1.31:8888
accepting connection from ('192.168.1.31', 51940)
Using selector: KqueueSelector
connecting to 192.168.1.31:8888
accepting connection from ('192.168.1.31', 51944)

Connection lost

Connection lost
Using selector: KqueueSelector
connecting to 192.168.1.31:8888
accepting connection from ('192.168.1.31', 51963)
Using selector: KqueueSelector
connecting to 192.168.1.31:8888
accepting connection from ('192.168.1.31', 51964)

[Errno 54] Connection reset by peer


Connection lost

Connection lost
Using selector: KqueueSelector
connecting to 192.168.1.31:8888
accepting connection from ('192.168.1.31', 51969)

Connection lost
Using selector: KqueueSelector
connecting to 192.168.1.31:8888
accepting connection from ('192.168.1.31', 51970)
Using selector: KqueueSelector
connecting to 192.168.1.31:8888
accepting connection from ('192.168.1.31', 51971)
Using selector: KqueueSelector
connecting to 192.168.1.31:8888
accepting connection from ('192.168.1.31', 51972)

[Errno 54] Connection reset by peer
[Errno 54] Connection reset by peer
[Errno 54] Connection reset by peer
